<?xml version="1.0"?>
<robot xmlns:xacro="http://www.ros.org/wiki/xacro"  >
    
    <xacro:include filename="joint_macro.xacro" />
    <xacro:include filename="gripper_fingers.xacro" />

    <material name="black">
        <color rgba="0 0 0 1"/>
    </material>
    <material name="white">
        <color rgba="1 1 1 1"/>
    </material>
    <link name="base_link">
    </link>
       <!-- CHASSIS -->
    <joint name="chassis_joint" type="revolute">
        <limit effort="5" velocity="2.1750" lower="-3.14" upper="3.14"/>
        <parent link="base_link"/>
        <child link="chassis_link" />
        <origin xyz="0 0 0"/>
        <axis xyz="0 0 1" />
    </joint>
    <link name="chassis_link">
        <visual>
            <origin xyz="0 0 0.2"/>
            <geometry>
                <box size="0.8 0.8 0.4" />
            </geometry>
            <material name="white"/>
        </visual>
    </link>
      
    <!-- BASE LOWER ARM -->
    <xacro:base_arm_generator suffix="lower" parent="chassis" ph="0.4" radius="0.2" length="0.8" />
    <!-- BASE UPPER ARM -->
    <xacro:base_arm_generator suffix="upper" parent="lower_arm" ph="0.8" radius="0.1" length="0.4" />
    <!-- BASE LAST ARM -->
    <xacro:base_arm_generator suffix="last" parent="yaw_arm" ph="0.01" radius="0.1" length="0.4" />

    
    <!-- LOWER ARM -->
    <xacro:arm_generator suffix="lower" parent="base_lower_arm" ph="0.2" sizex="0.4"  sizey="0.4" sizez="0.8" upper="1" lower="0" />
    <!-- UPPER ARM -->
    <xacro:arm_generator suffix="upper" parent="base_upper_arm" ph="0.1" sizex="0.4"  sizey="0.4" sizez="0.8" upper="1" lower="0" />
    <!-- LAST ARM -->
    <xacro:arm_generator suffix="last"  parent="base_last_arm"  ph="0.1" sizex="0.15" sizey="0.15" sizez="0.3" upper="1" lower="-1" />
    <!-- YAW ARM  -->
    <joint name="yaw_arm_joint" type="revolute" >
        <limit effort="5" velocity="2.1750" lower="-3.14" upper="3.14"/>
        <parent link="upper_arm_link" />
        <child link="yaw_arm_link" />
        <origin xyz="0 0 0.8" />
        <axis xyz="0 0 1" />
    </joint> 
    <link name="yaw_arm_link">
        <visual>
            <origin xyz="0 0 0.005"/>
            <geometry>
                <cylinder radius="0.2" length="0.01"/>
            </geometry>
            <material name="white"/>
        </visual>
    </link>
    <!-- GRIPPER -->
    <!-- FINGERS MACRO -->
    <xacro:finger id="first" yaw="${pi/4}"/>
    <xacro:finger id="second" yaw="${3*pi/4}"/>
    <xacro:finger id="third" yaw="${5*pi/4}"/>
    <xacro:finger id="fourth" yaw="${7*pi/4}"/>

</robot>